<robot name="my_bot"><link name="0_0"><visual><origin xyz="0.0 -5.0 2.0" rpy="0 0 0" /><geometry><box size="0.0 -5.0 2.0" /></geometry><material name="color_0_0"><color rgba="0.0 0.0 0.5 1" /></material></visual></link><link name="0_1"><visual><origin xyz="0.0 -4.0 2.0" rpy="0 0 0" /><geometry><box size="0.0 -1.0 0.0" /></geometry><material name="color_0_1"><color rgba="0.0 0.2 0.5 1" /></material></visual></link><link name="0_2"><visual><origin xyz="0.0 -3.0 -2.0" rpy="0 0 0" /><geometry><box size="0.0 -1.0 4.0" /></geometry><material name="color_0_2"><color rgba="0.0 0.4 0.5 1" /></material></visual></link><link name="0_3"><visual><origin xyz="-4.0 -4.0 -2.0" rpy="0 0 0" /><geometry><box size="4.0 1.0 0.0" /></geometry><material name="color_0_3"><color rgba="0.0 0.6000000000000001 0.5 1" /></material></visual></link><link name="1_0"><visual><origin xyz="0.0 -10.0 2.0" rpy="0 0 0" /><geometry><box size="0.0 -10.0 2.0" /></geometry><material name="color_1_0"><color rgba="0.2 0.0 0.5 1" /></material></visual></link><link name="1_1"><visual><origin xyz="0.0 -11.0 2.0" rpy="0 0 0" /><geometry><box size="0.0 1.0 0.0" /></geometry><material name="color_1_1"><color rgba="0.2 0.2 0.5 1" /></material></visual></link><link name="1_2"><visual><origin xyz="0.0 -12.0 -2.0" rpy="0 0 0" /><geometry><box size="0.0 1.0 4.0" /></geometry><material name="color_1_2"><color rgba="0.2 0.4 0.5 1" /></material></visual></link><link name="1_3"><visual><origin xyz="-4.0 -11.0 -2.0" rpy="0 0 0" /><geometry><box size="4.0 -1.0 0.0" /></geometry><material name="color_1_3"><color rgba="0.2 0.6000000000000001 0.5 1" /></material></visual></link><link name="2_0"><visual><origin xyz="10.0 -10.0 2.0" rpy="0 0 0" /><geometry><box size="10.0 -10.0 2.0" /></geometry><material name="color_2_0"><color rgba="0.4 0.0 0.5 1" /></material></visual></link><link name="2_1"><visual><origin xyz="10.0 -11.0 2.0" rpy="0 0 0" /><geometry><box size="0.0 1.0 0.0" /></geometry><material name="color_2_1"><color rgba="0.4 0.2 0.5 1" /></material></visual></link><link name="2_2"><visual><origin xyz="10.0 -12.0 -2.0" rpy="0 0 0" /><geometry><box size="0.0 1.0 4.0" /></geometry><material name="color_2_2"><color rgba="0.4 0.4 0.5 1" /></material></visual></link><link name="2_3"><visual><origin xyz="6.0 -11.0 -2.0" rpy="0 0 0" /><geometry><box size="4.0 -1.0 0.0" /></geometry><material name="color_2_3"><color rgba="0.4 0.6000000000000001 0.5 1" /></material></visual></link><link name="3_0"><visual><origin xyz="10.0 -5.0 2.0" rpy="0 0 0" /><geometry><box size="10.0 -5.0 2.0" /></geometry><material name="color_3_0"><color rgba="0.6000000000000001 0.0 0.5 1" /></material></visual></link><link name="3_1"><visual><origin xyz="10.0 -4.0 2.0" rpy="0 0 0" /><geometry><box size="0.0 -1.0 0.0" /></geometry><material name="color_3_1"><color rgba="0.6000000000000001 0.2 0.5 1" /></material></visual></link><link name="3_2"><visual><origin xyz="10.0 -3.0 -2.0" rpy="0 0 0" /><geometry><box size="0.0 -1.0 4.0" /></geometry><material name="color_3_2"><color rgba="0.6000000000000001 0.4 0.5 1" /></material></visual></link><link name="3_3"><visual><origin xyz="6.0 -4.0 -2.0" rpy="0 0 0" /><geometry><box size="4.0 1.0 0.0" /></geometry><material name="color_3_3"><color rgba="0.6000000000000001 0.6000000000000001 0.5 1" /></material></visual></link><link name="base"><visual><origin xyz="0 0 0" rpy="0 0 0" /><geometry><box size="0.1 0.1 0.1" /></geometry></visual></link><joint name="0_0" type="fixed"><parent link="base" /><child link="0_0" /><origin xyz="0.0 -5.0 2.0" rpy="0 0 0" /><axis xyz="1.0 -0.0 -0.0" /><limit lower="-3.14" upper="3.14" effort="1.0" velocity="1.0" /></joint><joint name="0_1" type="revolute"><parent link="0_0" /><child link="0_1" /><origin xyz="0.0 -1.0 0.0" rpy="0 0 0" /><axis xyz="-0.0 -1.0 -0.0" /><limit lower="-3.14" upper="3.14" effort="1.0" velocity="1.0" /></joint><joint name="0_2" type="revolute"><parent link="0_1" /><child link="0_2" /><origin xyz="0.0 -1.0 4.0" rpy="0 0 0" /><axis xyz="-0.0 -1.0 -0.0" /><limit lower="-3.14" upper="3.14" effort="1.0" velocity="1.0" /></joint><joint name="0_3" type="revolute"><parent link="0_2" /><child link="0_3" /><origin xyz="4.0 1.0 0.0" rpy="0 0 0" /><axis xyz="-0.0 1.0 -0.0" /><limit lower="-3.14" upper="3.14" effort="1.0" velocity="1.0" /></joint><joint name="1_0" type="fixed"><parent link="base" /><child link="1_0" /><origin xyz="0.0 -10.0 2.0" rpy="0 0 0" /><axis xyz="1.0 -0.0 -0.0" /><limit lower="-3.14" upper="3.14" effort="1.0" velocity="1.0" /></joint><joint name="1_1" type="revolute"><parent link="1_0" /><child link="1_1" /><origin xyz="0.0 1.0 0.0" rpy="0 0 0" /><axis xyz="-0.0 1.0 -0.0" /><limit lower="-3.14" upper="3.14" effort="1.0" velocity="1.0" /></joint><joint name="1_2" type="revolute"><parent link="1_1" /><child link="1_2" /><origin xyz="0.0 1.0 4.0" rpy="0 0 0" /><axis xyz="-0.0 1.0 -0.0" /><limit lower="-3.14" upper="3.14" effort="1.0" velocity="1.0" /></joint><joint name="1_3" type="revolute"><parent link="1_2" /><child link="1_3" /><origin xyz="4.0 -1.0 0.0" rpy="0 0 0" /><axis xyz="-0.0 -1.0 -0.0" /><limit lower="-3.14" upper="3.14" effort="1.0" velocity="1.0" /></joint><joint name="2_0" type="fixed"><parent link="base" /><child link="2_0" /><origin xyz="10.0 -10.0 2.0" rpy="0 0 0" /><axis xyz="1.0 -0.0 -0.0" /><limit lower="-3.14" upper="3.14" effort="1.0" velocity="1.0" /></joint><joint name="2_1" type="revolute"><parent link="2_0" /><child link="2_1" /><origin xyz="0.0 1.0 0.0" rpy="0 0 0" /><axis xyz="-0.0 1.0 -0.0" /><limit lower="-3.14" upper="3.14" effort="1.0" velocity="1.0" /></joint><joint name="2_2" type="revolute"><parent link="2_1" /><child link="2_2" /><origin xyz="0.0 1.0 4.0" rpy="0 0 0" /><axis xyz="-0.0 1.0 -0.0" /><limit lower="-3.14" upper="3.14" effort="1.0" velocity="1.0" /></joint><joint name="2_3" type="revolute"><parent link="2_2" /><child link="2_3" /><origin xyz="4.0 -1.0 0.0" rpy="0 0 0" /><axis xyz="-0.0 -1.0 -0.0" /><limit lower="-3.14" upper="3.14" effort="1.0" velocity="1.0" /></joint><joint name="3_0" type="fixed"><parent link="base" /><child link="3_0" /><origin xyz="10.0 -5.0 2.0" rpy="0 0 0" /><axis xyz="1.0 -0.0 -0.0" /><limit lower="-3.14" upper="3.14" effort="1.0" velocity="1.0" /></joint><joint name="3_1" type="revolute"><parent link="3_0" /><child link="3_1" /><origin xyz="0.0 -1.0 0.0" rpy="0 0 0" /><axis xyz="-0.0 -1.0 -0.0" /><limit lower="-3.14" upper="3.14" effort="1.0" velocity="1.0" /></joint><joint name="3_2" type="revolute"><parent link="3_1" /><child link="3_2" /><origin xyz="0.0 -1.0 4.0" rpy="0 0 0" /><axis xyz="-0.0 -1.0 -0.0" /><limit lower="-3.14" upper="3.14" effort="1.0" velocity="1.0" /></joint><joint name="3_3" type="revolute"><parent link="3_2" /><child link="3_3" /><origin xyz="4.0 1.0 0.0" rpy="0 0 0" /><axis xyz="-0.0 1.0 -0.0" /><limit lower="-3.14" upper="3.14" effort="1.0" velocity="1.0" /></joint></robot>